Workbook

Sheet Sheet1
A1: AU | B1: TI | C1: SO | D1: PY
A2: Abebe,A;Assemie,A; | B2: Mercadeo interno, compromiso organizacional y su relación con el clima laboral en los docentes universitarios | C2: Heliyon | D2: 2023
A3: Aftab,N;Shah,SAA;Khan,Z; | B3: The moderating effect of gender on the relationship between organizational commitment and organizational citizenship behavior in Pakistani university teachers | C3: Cogent Psychology | D3: 2021
A4: Aspan,H;Rosli,R;Prabowo,A;Wahyuni,ES; | B4: Assessment of Lecturer Work Effectiveness: Mediating Organizational Citizen Behavior Based on Organizational Commitment and Work Motivation | C4: Journal of Ecohumanism | D4: 2025
A5: Ahmad,AYAB;Kolachina,S;Rajest,SS;Singh,M;Mishra,A;Sundar,SS; | B5: Impact of digital HRM on academicians' performance: exploring the mediating role of organisational commitment | C5: International Journal of Intelligent Enterprise | D5: 2025
A6: Batugal, MLC; Tindowen, DJC; | B6: Influence of Organizational Culture on Teachers' Organizational Commitment and Job Satisfaction: The Case of Catholic Higher Education Institutions in the Philippines | C6: Universal Journal of Educational Research | D6: 2019
A7: Cassim,N;Botha,CJ;Botha,D;Bisschoff,C; | B7: The organisational commitment of academic personnel during WFH within private higher education, South Africa | C7: SA Journal of Industrial Psychology | D7: 2024
A8: Chalim,AS; | B8: Effect of job-insecurity, organizational commitment, job satisfaction on turnover intention: a case study of newcomer lecturers at private Islamic universities in East Java Province, Indonesia | C8: The Indonesian Journal of the Social Sciences | D8: 2018
A9: Chasanah,U;Suyanto,M;Istanto,Y; | B9: Internal Marketing in Its Influence on Organizational Commitment: the Mediation of Job Satisfaction and Organizational Justice | C9: WSEAS Transactions on Business and Economics | D9: 2021
A10: Cheasakul,U;Varma,P; | B10: The influence of passion and empowerment on organizational citizenship behavior of teachers mediated by organizational commitment | C10: Contaduría y Administración | D10: 2016
A11: Chen,KH;Hsieh,MHM;Maritz,A;Shieh,CJ; | B11: What affects organizational identification in universities? Examining the effects of psychological contract on organizational identification and commitment of teachers | C11: Acta Psychologica | D11: 2025
A12: Sousa,IF;Mendonça,H; | B12: Burnout em Professores Universitários: Impacto de Percepções de Justiça e Comprometimento Afetivo | C12: Psicologia: Teoria e Pesquisa | D12: 2009
A13: Djaelania,AK;Sanusib,A;Trianmantob,B; | B13: Spiritual leadership, job Satisfaction, and its effect on organizational commitment and organizational citizenship behavior | C13: Management Science Letters | D13: 2020
... A74: Zhou,SL;Hamid,AH;Alias,BS; | B74: Deconstructing Distributed Leadership: How Self-Efficacy and Organizational Commitment Shape Teacher Satisfaction in Chinese Universities | C74: Malaysian Online Journal of Educational Management (MOJEM) | D74: 2025

Sheet Sheet2
A1: PY | B1: Quantidade | L1: =IFERROR(__xludf.DUMMYFUNCTION("QUERY(Sheet1!C2:C9483, ""select C, count(C) where C is not null group by C order by count(C) desc label C 'Revistas', count(C) 'Quantidade'"")"),"Revistas") -> Revistas | M1: =IFERROR(__xludf.DUMMYFUNCTION("""COMPUTED_VALUE"""),"Quantidade") -> Quantidade | W1: Autores
A2: 2003 | B2: =COUNTIF(Sheet1!D:D, A2) -> 1 | L2: =IFERROR(__xludf.DUMMYFUNCTION("""COMPUTED_VALUE"""),"SA Journal of Human Resource Management") -> SA Journal of Human Resource Management | M2: =IFERROR(__xludf.DUMMYFUNCTION("""COMPUTED_VALUE"""),3.0) -> 3 | W2: =IFERROR(__xludf.DUMMYFUNCTION("ARRAYFORMULA(TRIM(FLATTEN(SPLIT(Sheet1!A2:A9483, "";""))))"),"Abebe,A") -> Abebe,A
A3: 2004 | B3: =COUNTIF(Sheet1!D:D, A3) -> 0 | L3: =IFERROR(__xludf.DUMMYFUNCTION("""COMPUTED_VALUE"""),"Apuntes Universitarios") -> Apuntes Universitarios | M3: =IFERROR(__xludf.DUMMYFUNCTION("""COMPUTED_VALUE"""),2.0) -> 2 | W3: =IFERROR(__xludf.DUMMYFUNCTION("""COMPUTED_VALUE"""),"Assemie,A") -> Assemie,A
A4: 2005 | B4: =COUNTIF(Sheet1!D:D, A4) -> 0 | L4: =IFERROR(__xludf.DUMMYFUNCTION("""COMPUTED_VALUE"""),"Environment and Social Psychology") -> Environment and Social Psychology | M4: =IFERROR(__xludf.DUMMYFUNCTION("""COMPUTED_VALUE"""),2.0) -> 2 | W4: =IFERROR(__xludf.DUMMYFUNCTION("""COMPUTED_VALUE"""),"")
A5: 2006 | B5: =COUNTIF(Sheet1!D:D, A5) -> 0 | L5: =IFERROR(__xludf.DUMMYFUNCTION("""COMPUTED_VALUE"""),"Frontiers in Psychology") -> Frontiers in Psychology | M5: =IFERROR(__xludf.DUMMYFUNCTION("""COMPUTED_VALUE"""),2.0) -> 2 | W5: =IFERROR(__xludf.DUMMYFUNCTION("""COMPUTED_VALUE"""),"")
A6: 2007 | B6: =COUNTIF(Sheet1!D:D, A6) -> 0 | L6: =IFERROR(__xludf.DUMMYFUNCTION("""COMPUTED_VALUE"""),"International Journal of Evaluation and Research in Education") -> International Journal of Evaluation and Research in Education | M6: =IFERROR(__xludf.DUMMYFUNCTION("""COMPUTED_VALUE"""),2.0) -> 2 | W6: =IFERROR(__xludf.DUMMYFUNCTION("""COMPUTED_VALUE"""),"")
A7: 2008 | B7: =COUNTIF(Sheet1!D:D, A7) -> 0 | L7: =IFERROR(__xludf.DUMMYFUNCTION("""COMPUTED_VALUE"""),"International Journal of Higher Education") -> International Journal of Higher Education | M7: =IFERROR(__xludf.DUMMYFUNCTION("""COMPUTED_VALUE"""),2.0) -> 2 | W7: =IFERROR(__xludf.DUMMYFUNCTION("""COMPUTED_VALUE"""),"")
A8: 2009 | B8: =COUNTIF(Sheet1!D:D, A8) -> 1 | L8: =IFERROR(__xludf.DUMMYFUNCTION("""COMPUTED_VALUE"""),"Journal of Ecohumanism") -> Journal of Ecohumanism | M8: =IFERROR(__xludf.DUMMYFUNCTION("""COMPUTED_VALUE"""),2.0) -> 2 | W8: =IFERROR(__xludf.DUMMYFUNCTION("""COMPUTED_VALUE"""),"")
A9: 2010 | B9: =COUNTIF(Sheet1!D:D, A9) -> 0 | L9: =IFERROR(__xludf.DUMMYFUNCTION("""COMPUTED_VALUE"""),"Management Science Letters") -> Management Science Letters | M9: =IFERROR(__xludf.DUMMYFUNCTION("""COMPUTED_VALUE"""),2.0) -> 2 | W9: =IFERROR(__xludf.DUMMYFUNCTION("""COMPUTED_VALUE"""),"")
A10: 2011 | B10: =COUNTIF(Sheet1!D:D, A10) -> 0 | L10: =IFERROR(__xludf.DUMMYFUNCTION("""COMPUTED_VALUE"""),"Revista Venezolana De Gerencia") -> Revista Venezolana De Gerencia | M10: =IFERROR(__xludf.DUMMYFUNCTION("""COMPUTED_VALUE"""),2.0) -> 2 | W10: =IFERROR(__xludf.DUMMYFUNCTION("""COMPUTED_VALUE"""),"")
A11: 2012 | B11: =COUNTIF(Sheet1!D:D, A11) -> 2 | L11: =IFERROR(__xludf.DUMMYFUNCTION("""COMPUTED_VALUE"""),"SAGE Open") -> SAGE Open | M11: =IFERROR(__xludf.DUMMYFUNCTION("""COMPUTED_VALUE"""),2.0) -> 2 | W11: =IFERROR(__xludf.DUMMYFUNCTION("""COMPUTED_VALUE"""),"Aftab,N") -> Aftab,N
A12: 2013 | B12: =COUNTIF(Sheet1!D:D, A12) -> 2 | L12: =IFERROR(__xludf.DUMMYFUNCTION("""COMPUTED_VALUE""")," Journal of Technical Education and Training") -> Journal of Technical Education and Training | M12: =IFERROR(__xludf.DUMMYFUNCTION("""COMPUTED_VALUE"""),1.0) -> 1 | W12: =IFERROR(__xludf.DUMMYFUNCTION("""COMPUTED_VALUE"""),"Shah,SAA") -> Shah,SAA
A13: 2014 | B13: =COUNTIF(Sheet1!D:D, A13) -> 1 | L13: =IFERROR(__xludf.DUMMYFUNCTION("""COMPUTED_VALUE"""),"Acta Colombiana de Psicología") -> Acta Colombiana de Psicología | M13: =IFERROR(__xludf.DUMMYFUNCTION("""COMPUTED_VALUE"""),1.0) -> 1 | W13: =IFERROR(__xludf.DUMMYFUNCTION("""COMPUTED_VALUE"""),"Khan,Z") -> Khan,Z
A14: 2015 | B14: =COUNTIF(Sheet1!D:D, A14) -> 1 | L14: =IFERROR(__xludf.DUMMYFUNCTION("""COMPUTED_VALUE"""),"Acta Psychologica") -> Acta Psychologica | M14: =IFERROR(__xludf.DUMMYFUNCTION("""COMPUTED_VALUE"""),1.0) -> 1 | W14: =IFERROR(__xludf.DUMMYFUNCTION("""COMPUTED_VALUE"""),"")
A15: 2016 | B15: =COUNTIF(Sheet1!D:D, A15) -> 3 | L15: =IFERROR(__xludf.DUMMYFUNCTION("""COMPUTED_VALUE"""),"Asian Social Science") -> Asian Social Science | M15: =IFERROR(__xludf.DUMMYFUNCTION("""COMPUTED_VALUE"""),1.0) -> 1 | W15: =IFERROR(__xludf.DUMMYFUNCTION("""COMPUTED_VALUE"""),"")
A16: 2017 | B16: =COUNTIF(Sheet1!D:D, A16) -> 0 | L16: =IFERROR(__xludf.DUMMYFUNCTION("""COMPUTED_VALUE"""),"BMC nursing") -> BMC nursing | M16: =IFERROR(__xludf.DUMMYFUNCTION("""COMPUTED_VALUE"""),1.0) -> 1 | W16: =IFERROR(__xludf.DUMMYFUNCTION("""COMPUTED_VALUE"""),"")
A17: 2018 | B17: =COUNTIF(Sheet1!D:D, A17) -> 2 | L17: =IFERROR(__xludf.DUMMYFUNCTION("""COMPUTED_VALUE"""),"Business Systems Research") -> Business Systems Research | M17: =IFERROR(__xludf.DUMMYFUNCTION("""COMPUTED_VALUE"""),1.0) -> 1 | W17: =IFERROR(__xludf.DUMMYFUNCTION("""COMPUTED_VALUE"""),"")
A18: 2019 | B18: =COUNTIF(Sheet1!D:D, A18) -> 6 | L18: =IFERROR(__xludf.DUMMYFUNCTION("""COMPUTED_VALUE"""),"Calitatea") -> Calitatea | M18: =IFERROR(__xludf.DUMMYFUNCTION("""COMPUTED_VALUE"""),1.0) -> 1 | W18: =IFERROR(__xludf.DUMMYFUNCTION("""COMPUTED_VALUE"""),"")
A19: 2020 | B19: =COUNTIF(Sheet1!D:D, A19) -> 7 | L19: =IFERROR(__xludf.DUMMYFUNCTION("""COMPUTED_VALUE"""),"Cogent Education") -> Cogent Education | M19: =IFERROR(__xludf.DUMMYFUNCTION("""COMPUTED_VALUE"""),1.0) -> 1 | W19: =IFERROR(__xludf.DUMMYFUNCTION("""COMPUTED_VALUE"""),"")
A20: 2021 | B20: =COUNTIF(Sheet1!D:D, A20) -> 4 | L20: =IFERROR(__xludf.DUMMYFUNCTION("""COMPUTED_VALUE"""),"Cogent Psychology ") -> Cogent Psychology | M20: =IFERROR(__xludf.DUMMYFUNCTION("""COMPUTED_VALUE"""),1.0) -> 1 | W20: =IFERROR(__xludf.DUMMYFUNCTION("""COMPUTED_VALUE"""),"Aspan,H") -> Aspan,H
A21: 2022 | B21: =COUNTIF(Sheet1!D:D, A21) -> 8 | D21: S | L21: =IFERROR(__xludf.DUMMYFUNCTION("""COMPUTED_VALUE"""),"Contaduría y Administración") -> Contaduría y Administración | M21: =IFERROR(__xludf.DUMMYFUNCTION("""COMPUTED_VALUE"""),1.0) -> 1 | W21: =IFERROR(__xludf.DUMMYFUNCTION("""COMPUTED_VALUE"""),"Rosli,R") -> Rosli,R
A22: 2023 | B22: =COUNTIF(Sheet1!D:D, A22) -> 7 | L22: =IFERROR(__xludf.DUMMYFUNCTION("""COMPUTED_VALUE"""),"Edelweiss Applied Science and Technology") -> Edelweiss Applied Science and Technology | M22: =IFERROR(__xludf.DUMMYFUNCTION("""COMPUTED_VALUE"""),1.0) -> 1 | W22: =IFERROR(__xludf.DUMMYFUNCTION("""COMPUTED_VALUE"""),"Prabowo,A") -> Prabowo,A
A23: 2024 | B23: =COUNTIF(Sheet1!D:D, A23) -> 11 | L23: =IFERROR(__xludf.DUMMYFUNCTION("""COMPUTED_VALUE"""),"Emerging Science Journal") -> Emerging Science Journal | M23: =IFERROR(__xludf.DUMMYFUNCTION("""COMPUTED_VALUE"""),1.0) -> 1 | W23: =IFERROR(__xludf.DUMMYFUNCTION("""COMPUTED_VALUE"""),"Wahyuni,ES") -> Wahyuni,ES
A24: 2025 | B24: 14 | L24: =IFERROR(__xludf.DUMMYFUNCTION("""COMPUTED_VALUE"""),"European Journal of Educational Research") -> European Journal of Educational Research | M24: =IFERROR(__xludf.DUMMYFUNCTION("""COMPUTED_VALUE"""),1.0) -> 1 | W24: =IFERROR(__xludf.DUMMYFUNCTION("""COMPUTED_VALUE"""),"")
A25: 2026 | B25: =COUNTIF(Sheet1!D:D, A25) -> 3 | L25: =IFERROR(__xludf.DUMMYFUNCTION("""COMPUTED_VALUE"""),"Formación universitaria") -> Formación universitaria | M25: =IFERROR(__xludf.DUMMYFUNCTION("""COMPUTED_VALUE"""),1.0) -> 1 | W25: =IFERROR(__xludf.DUMMYFUNCTION("""COMPUTED_VALUE"""),"")
L26: =IFERROR(__xludf.DUMMYFUNCTION("""COMPUTED_VALUE"""),"Frontiers in Education") -> Frontiers in Education | M26: =IFERROR(__xludf.DUMMYFUNCTION("""COMPUTED_VALUE"""),1.0) -> 1 | W26: =IFERROR(__xludf.DUMMYFUNCTION("""COMPUTED_VALUE"""),"")
L27: =IFERROR(__xludf.DUMMYFUNCTION("""COMPUTED_VALUE"""),"Heliyon ") -> Heliyon | M27: =IFERROR(__xludf.DUMMYFUNCTION("""COMPUTED_VALUE"""),1.0) -> 1 | W27: =IFERROR(__xludf.DUMMYFUNCTION("""COMPUTED_VALUE"""),"")
L28: =IFERROR(__xludf.DUMMYFUNCTION("""COMPUTED_VALUE"""),"Horizontes. Revista de Investigación en Ciencias de la Educación") -> Horizontes. Revista de Investigación en Ciencias de la Educación | M28: =IFERROR(__xludf.DUMMYFUNCTION("""COMPUTED_VALUE"""),1.0) -> 1 | W28: =IFERROR(__xludf.DUMMYFUNCTION("""COMPUTED_VALUE"""),"")
L29: =IFERROR(__xludf.DUMMYFUNCTION("""COMPUTED_VALUE"""),"International Journal of Intelligent Enterprise") -> International Journal of Intelligent Enterprise | M29: =IFERROR(__xludf.DUMMYFUNCTION("""COMPUTED_VALUE"""),1.0) -> 1 | W29: =IFERROR(__xludf.DUMMYFUNCTION("""COMPUTED_VALUE"""),"Ahmad,AYAB") -> Ahmad,AYAB
L30: =IFERROR(__xludf.DUMMYFUNCTION("""COMPUTED_VALUE"""),"International Journal of Learning, Teaching and Educational Research ") -> International Journal of Learning, Teaching and Educational Research | M30: =IFERROR(__xludf.DUMMYFUNCTION("""COMPUTED_VALUE"""),1.0) -> 1 | W30: =IFERROR(__xludf.DUMMYFUNCTION("""COMPUTED_VALUE"""),"Kolachina,S") -> Kolachina,S
L31: =IFERROR(__xludf.DUMMYFUNCTION("""COMPUTED_VALUE"""),"International Research Journal of Multidisciplinary Scope (IRJMS)") -> International Research Journal of Multidisciplinary Scope (IRJMS) | M31: =IFERROR(__xludf.DUMMYFUNCTION("""COMPUTED_VALUE"""),1.0) -> 1 | W31: =IFERROR(__xludf.DUMMYFUNCTION("""COMPUTED_VALUE"""),"Rajest,SS") -> Rajest,SS
L32: =IFERROR(__xludf.DUMMYFUNCTION("""COMPUTED_VALUE"""),"International Review of Management and Marketing") -> International Review of Management and Marketing | M32: =IFERROR(__xludf.DUMMYFUNCTION("""COMPUTED_VALUE"""),1.0) -> 1 | W32: =IFERROR(__xludf.DUMMYFUNCTION("""COMPUTED_VALUE"""),"Singh,M") -> Singh,M
L33: =IFERROR(__xludf.DUMMYFUNCTION("""COMPUTED_VALUE"""),"International and Multidisciplinary Journal of Social Sciences") -> International and Multidisciplinary Journal of Social Sciences | M33: =IFERROR(__xludf.DUMMYFUNCTION("""COMPUTED_VALUE"""),1.0) -> 1 | W33: =IFERROR(__xludf.DUMMYFUNCTION("""COMPUTED_VALUE"""),"Mishra,A") -> Mishra,A
L34: =IFERROR(__xludf.DUMMYFUNCTION("""COMPUTED_VALUE"""),"Journal of Economics and Management") -> Journal of Economics and Management | M34: =IFERROR(__xludf.DUMMYFUNCTION("""COMPUTED_VALUE"""),1.0) -> 1 | W34: =IFERROR(__xludf.DUMMYFUNCTION("""COMPUTED_VALUE"""),"Sundar,SS") -> Sundar,SS
L35: =IFERROR(__xludf.DUMMYFUNCTION("""COMPUTED_VALUE"""),"Journal of Law and Sustainable Development") -> Journal of Law and Sustainable Development | M35: =IFERROR(__xludf.DUMMYFUNCTION("""COMPUTED_VALUE"""),1.0) -> 1 | W35: =IFERROR(__xludf.DUMMYFUNCTION("""COMPUTED_VALUE"""),"")
L36: =IFERROR(__xludf.DUMMYFUNCTION("""COMPUTED_VALUE"""),"Journal of Logistics, Informatics and Service Science") -> Journal of Logistics, Informatics and Service Science | M36: =IFERROR(__xludf.DUMMYFUNCTION("""COMPUTED_VALUE"""),1.0) -> 1 | W36: =IFERROR(__xludf.DUMMYFUNCTION("""COMPUTED_VALUE"""),"")
L37: =IFERROR(__xludf.DUMMYFUNCTION("""COMPUTED_VALUE"""),"Malaysian Online Journal of Educational Management (MOJEM)") -> Malaysian Online Journal of Educational Management (MOJEM) | M37: =IFERROR(__xludf.DUMMYFUNCTION("""COMPUTED_VALUE"""),1.0) -> 1 | W37: =IFERROR(__xludf.DUMMYFUNCTION("""COMPUTED_VALUE"""),"")
L38: =IFERROR(__xludf.DUMMYFUNCTION("""COMPUTED_VALUE"""),"Mendive. Revista de Educación") -> Mendive. Revista de Educación | M38: =IFERROR(__xludf.DUMMYFUNCTION("""COMPUTED_VALUE"""),1.0) -> 1 | W38: =IFERROR(__xludf.DUMMYFUNCTION("""COMPUTED_VALUE"""),"Batugal, MLC") -> Batugal, MLC
L39: =IFERROR(__xludf.DUMMYFUNCTION("""COMPUTED_VALUE"""),"Multidisciplinary Reviews") -> Multidisciplinary Reviews | M39: =IFERROR(__xludf.DUMMYFUNCTION("""COMPUTED_VALUE"""),1.0) -> 1 | W39: =IFERROR(__xludf.DUMMYFUNCTION("""COMPUTED_VALUE"""),"Tindowen, DJC") -> Tindowen, DJC
L40: =IFERROR(__xludf.DUMMYFUNCTION("""COMPUTED_VALUE"""),"Nova scientia") -> Nova scientia | M40: =IFERROR(__xludf.DUMMYFUNCTION("""COMPUTED_VALUE"""),1.0) -> 1 | W40: =IFERROR(__xludf.DUMMYFUNCTION("""COMPUTED_VALUE"""),"")
...

Sheet Sheet3
A1: AU | B1: PY | C1: Nome da(s) instituição(ões) | D1: País | E1: Continente | F1: Nível de análise | G1: Temáticas relacionadas | H1: Abordagem centrada na pessoa | I1: Tipo de pesquisa | J1: N° de professores universtiários | K1: Tipo de instrumento | L1: Principais achados
A2: Abebe,A;Assemie,A; | B2: 2023 | C2: Universidade de Debre Markos | D2: Etiópia | E2: África | F2: Tridimensional (Afetivo, Instrumental e Normativo) | G2: Comprometimento Organizacional (CO); Desempenho no Trabalho (Job Performance) | H2: Não | I2: Quantitativa | J2: 239 | K2: Escala de Comprometimento de Meyer e Allen (1991) Qestionário de qualidade de vida no trabalho de Walton (1975) | L2: Identificou-se um nível moderado de CO e desempenho. Houve uma correlação positiva e significativa entre o comprometimento (especialmente o afetivo e normativo) e o desempenho dos professores. O comprometimento afetivo foi o preditor mais forte do desempenho.
A3: Aftab,N;Shah,SAA;Khan,Z; | B3: 2021 | C3: Universidades em Islamabad, Rawalpindi, Attock e Wah Cantt | D3: Paquistão | E3: Ásia | F3: Unidimensional | G3: CO; Comportamento de Cidadania Organizacional (OCB) | H3: Não | I3: Quantitativa | J3: 250 | K3: Escala de Comportamento de Cidadania Organizacional (Williams & Anderson, 1991) Questionário de Comprometimento Organizacional (OCQ) Mowday et al. (1982) | L3: Os resultados indicaram que o comprometimento organizacional previu de forma positiva e significativa o comportamento de cidadania organizacional. A análise de moderação revelou que, em um alto nível de comprometimento organizacional, as professoras apresentaram um nível mais alto de comportamento de cidadania organizacional do que os professores. Em relação às diferenças de gênero, as professoras obtiveram pontuações significativamente mais altas tanto em comprometimento organizacional quanto em comportamento de cidadania organizacional do que os professores.
A4: Aspan,H;Rosli,R;Prabowo,A;Wahyuni,ES; | B4: 2025 | C4: Universidades privadas da cidade de Medan | D4: Indonésia | E4: Ásia | F4: Unidimensional | G4: CO; OCB; Motivação no Trabalho; Eficácia do Trabalho do Docente. | H4: Não | I4: Quantitativa | J4: 120 | K4: Não especificado | L4: Os resultados explicam que o CO não tem um efeito direto, positivo e insignificante sobre a eficácia no trabalho e um um efeito indireto e significativo sobre a eficácia no trabalho por meio do comportamento de cidadania organizacional.
A5: Ahmad,AYAB;Kolachina,S;Rajest,SS;Singh,M;Mishra,A;Sundar,SS; | B5: 2025 | C5: Universidades em Uttar Pradesh | D5: Índia | E5: Ásia | F5: Tridimensional (Afetivo, Instrumental e Normativo) | G5: Gestão Digital de Recursos Humanos; CO; Desempenho dos Acadêmicos (Academicians' Performance). | H5: Não | I5: Quantitativa | J5: 400 | K5: Não especificado | L5: Os resultados destacam a necessidade de treinamentos online concentrados e práticas de RH que incentivem o comprometimento afetivo, ao mesmo tempo que eliminam as influências negativas de outras formas de comprometimento.
A6: Batugal, MLC; Tindowen, DJC; | B6: 2019 | C6: Instituições Católicas de Ensino Superior | D6: Filipinas | E6: Ásia | F6: Unidimensional | G6: CO; Inteligência Emocional (IE); Professores de Escolas Católicas. | H6: Não | I6: Quantitativa | J6: 129 | K6: Escala de Comprometimento de Meyer e Allen (2006); Instrumento de Avaliação da Cultura Organizacional de Cameron e Quinn (1999). Questionário de Satisfação no Trabalho do Apostolado Educacional São Paulo de Chartres (SPCEA) | L6: Os resultados enfatizaram que a cultura organizacional fomenta um alto nível de CO, além de uma relação positiva com a satisfação no trabalho dos professores.
A7: Cassim,N;Botha,CJ;Botha,D;Bisschoff,C; | B7: 2024 | C7: Instituição Privada de Ensino Superior | D7: África do Sul | E7: África | F7: Tridimensional (Afetivo, Instrumental e Normativo) | G7: CO; Trabalho Remoto (Work from Home - WFH); Instituições de Ensino Superior Privadas. | H7: Não | I7: Quantitativa | J7: 204 | K7: Escala de Comprometimento de Meyer e Allen (1993). | L7: O estudo constatou que, apesar das dificuldades e do desconforto causados pela rápida transição para o trabalho remoto devido à pandemia global de COVID-19, os níveis de comprometimento organizacional do corpo docente, especificamente o comprometimento afetivo e normativo, foram mantidos.
A8: Chalim,AS; | B8: 2018 | C8: Universidades islâmicas privadas na província de Java Oriental | D8: Indonésia | E8: Ásia | F8: Unidimensional | H8: Não | I8: Quantitativa | K8: Não especificado | L8: O estudo constatou que a insegurança no trabalho influencia a satisfação no trabalho e o comprometimento organizacional. Além disso, a satisfação no trabalho e o comprometimento organizacional têm impactos positivos na intenção de rotatividade. Em contrapartida, a insegurança no trabalho não teve um impacto direto significativo na intenção de rotatividade, mas teve um efeito indireto que influencia a satisfação no trabalho e o comprometimento organizacional.
A9: Chasanah,U;Suyanto,M;Istanto,Y; | B9: 2021 | C9: Universidade privada | D9: Indonésia | E9: Ásia | F9: Unidimensional | H9: Não | I9: Quantitativa | K9: Não especificado | L9: Por fim, os resultados mostraram que sete das nove hipóteses foram comprovadas. Por outro lado, para as demais hipóteses, os resultados mostraram que a justiça organizacional e o marketing interno não tiveram efeito direto sobre o comprometimento organizacional. Além disso, constatou-se que a justiça organizacional e a satisfação no trabalho atuaram como mediadoras na relação entre marketing interno e comprometimento organizacional.
A10: Cheasakul,U;Varma,P; | B10: 2016 | C10: Universidade privada | D10: Tailândia | E10: Ásia | F10: Tridimensional (Afetivo, Instrumental e Normativo) | H10: Não | I10: Quantitativa | K10: Escala de Comportamento de Cidadania Organizacional, adaptada por Podsakoff e Mackenzie (1990) da versão de Organ (1988) Escala de Paixão, desenvolvida por Vallerand, Carbonneau, Fernet e Guay (2008) Escala de Empoderamento do Participante Escolar, desenvolvida por Short e Rinehart (1992) Escala de Compromisso Organizacional , que foi modificada a partir da escala original de Meyer e Allen (1991) por Meyer, Allen e Smith (1993). | L10: Existem relações entre paixão pelo ensino, empoderamento do professor e comprometimento organizacional no comportamento de cidadania organizacional dos professores.
A11: Chen,KH;Hsieh,MHM;Maritz,A;Shieh,CJ; | B11: 2025 | C11: Universidades públicas e privadas | D11: Taiwan | E11: Ásia | F11: Unidimensional | H11: Não | I11: Quantitativa | K11: Não especificado | L11: Quando os objetivos do corpo docente se alinham aos objetivos institucionais, eles demonstram maior comprometimento organizacional, o que facilita o funcionamento das operações diárias.
A12: Sousa,IF;Mendonça,H; | B12: 2009 | C12: Instituição de ensino superior privada | D12: Brasil | E12: América Latina | F12: Unidimensional | H12: Não | I12: Quantitativa | K12: Maslach Burnout Inventory (MBI); Escala de Percepção de Justiça Organizacional (EPJO) Questionário de Comprometimento Organizacional (OCQ) | L12: O poder mediacional do comprometimento é confirmado na relação entre percepção de justiça distributiva e exaustão. Conclui-se que a percepção de injustiça na forma de distribuição de recursos pode levar o professor universitário à exaustão, ou que pode ter probabilidade aumentada diante da falta de comprometimento.
A13: Djaelania,AK;Sanusib,A;Trianmantob,B; | B13: 2020 | C13: Universidades islâmicas privadas localizadas em Malang | D13: Indonésia | E13: Ásia | F13: Unidimensional | H13: Não | I13: Quantitativa | K13: Escala de comprometimento organizacional de Allen e Meyer (1990, 1993) Escala de liderança espiritual de Fry (2003) e Fry, Vitucci e Cedillo (2005) Escala de satisfação no trabalho de Hulin e Judge (2003) Escala de comportamento de cidadania org. de Podsakoff (2000) | L13: Os resultados da modelagem de equações estruturais indicaram um efeito direto entre liderança espiritual e comportamento de cidadania organizacional (CCO), e um efeito indireto do comprometimento organizacional na relação entre liderança espiritual e satisfação no trabalho em relação ao CCO
A14: Duran-Ponce,GS;Flores-Mamani,E; | B14: 2025 | C14: Universidade Nacional do Altiplano Universidade Nacional de Juliaca | D14: Peru | E14: América Latina | F14: Tridimensional (Afetivo, Instrumental e Normativo) | H14: Não | I14: Quantitativa | K14: Para a variável marketing interno, foi utilizado o modelo de Bohnenberger Para a segunda variável, o modelo de comprometimento do colaborador de Allen e Meyer Para o clima organizacional, o questionário proposto por Litwin e Stringer | L14: Os resultados mostram uma correlação positiva e significativa entre as variáveis. A relação entre marketing interno e clima organizacional é moderada, enquanto a relação entre comprometimento organizacional e clima organizacional é fraca. Conclui-se que quanto melhores as variáveis de marketing interno e comprometimento organizacional, melhor o clima organizacional nas universidades analisadas.
A15: Fan,J;Chang,YC; | B15: 2025 | C15: Universidades privadas de graduação na província de Yunna | D15: China | E15: Ásia | F15: Unidimensional | H15: Não | I15: Quantitativa | K15: Escala de Comprometimento Organizacional desenvolvida por Wang Escala de Escala de Bem-Estar Ocupacional desenvolvida por Zhang e Jin Escala de Desenvolvimento Profissional desenvolvida por Wang | L15: Os resultados confirmaram que o CO dos professores melhorou significativamente seu Desenvolvimento Profissional (ÿ = 0,253; IC 95%: 0,163 - 0,345; p < 0,001), e o Bem-Estar-Ocupacional mediou parcialmente essa relação (ÿ = 0,038; IC 95%: 0,019 - 0,067; p < 0,001). Os resultados sugerem que o fortalecimento da coordenação motora dos professores é crucial para promover seu desenvolvimento profissional, com especial atenção ao papel mediador fundamental do bem-estar organizacional.
A16: Fatimah,F;Sarbaini,S;Arisanty,D; | B16: 2022 | C16: Universidades públicas da província de Kalimantan do Sul | D16: Indonésia | E16: Ásia | F16: Tridimensional (Afetivo, Instrumental e Normativo) | H16: Não | I16: Quantitativa | K16: Escala comprometimento do colaborador de Allen e Meyer (1993) | L16: Os resultados indicam que a maioria dos docentes possui comprometimento de continuidade (CC), pois consideram os custos e benefícios associados ao término de seu vínculo com a universidade. Além disso, quando melhores oportunidades surgem, eles deixam suas universidades. Das variáveis demográficas selecionadas, apenas o nível de escolaridade e o tempo de serviço afetam significativamente o comprometimento dos professores universitários. Este estudo constata que os docentes e as universidades mantêm uma relação recíproca. Quando os docentes são tratados com profissionalismo, respondem com maior comprometimento, pois os reconhecem como uma parte essencial da organização.
A17: Figueira,DJ;Nascimento,JLRP;Almeida,MHRG; | B17: 2014 | C17: Universidade pública nacional | D17: Portugal | E17: Europa | F17: Tridimensional (Afetivo, Instrumental e Normativo) | H17: Não | I17: Quantitativa | K17: Escala de Meyer e Allen (1997), adaptada ao contexto português por Nascimento, Lopes e Salgueiro (2008). | L17: Os docentes são mais comprometidos com a profissão do que com a organização onde a exercem, o que está em consonância com outros estudos empíricos que utilizaram profissões com alta cultura e identificação profissional. O comprometimento do professor, seja com a profissão ou com a organização, é predominantemente de natureza afetiva e calculativa.
A18: Flores,RQ;Sullca,SP; | B18: 2020 | C18: Universidade Nacional Amazônica de Mãe de Deus | D18: Peru | E18: América Latina | F18: Tridimensional (Afetivo, Instrumental e Normativo) | H18: Não | I18: Mista | K18: Questionário de Dingeta (2013) de satisfação no trabalho Questionário adaptado e baseado na escala de CO de Meyer e Allen (1997) | L18: Existe uma relação significativa entre a satisfação no trabalho e o comprometimento organizacional entre os professores. A satisfação no trabalho não está relacionada ao compromisso com a continuidade, nem com o compromisso regulatório; no entanto, possui uma relação direta e significativa com o comprometimento afetivo.
A19: Galván-Vela,E;Ravina-Ripoll,R;Salazar-Altamirano,MA;Sorzano-Rodríguez,DM; | B19: 2024 | C19: Universidades públicas e privadas | D19: México | E19: América Latina | F19: Unidimensional | H19: Não | I19: Quantitativa | K19: Em relação à dimensão de felicidade no trabalho foi utilizada a escala de Ramírez -García et al. (2019) Quanto à variável comprometimento afetivo, foi utilizada a escala de Meyer e Allen (1991), apenas em sua dimensão “afetiva”, composta por seis itens. A justiça organizacional também foi avaliada utilizando-se uma escala de quinze itens desenvolvida por Niehoff e Moorman (1993). Em relação ao fator satisfação no trabalho, os autores desta pesquisa utilizaram a escala de cinco itens sugerida por Veray-Alicea (2016). Na intenção de rotacionar, foram utilizados os três itens da escala de Mobley et al. (1978). | L19: Os resultados do estudo mostram que, por um lado, as variáveis satisfação no trabalho, comprometimento organizacional e justiça organizacional estão inter-relacionadas entre esses docentes e, por outro lado, que essas variáveis explicam positivamente a felicidade no trabalho e negativamente a intenção de rotatividade
... A74: Zhou,SL;Hamid,AH;Alias,BS; | B74: 2025 | C74: Instituições de ensino superior | D74: China | E74: Ásia | F74: Unidimensional | H74: Não | I74: Quantitativa | K74: Inventário de DL (DLI) desenvolvido por Hulpia et al. (2009); Escala de Autoeficácia desenvolvida por Andrews e Whitney (1976); | L74: A liderança distribuída (LD) pode ter um impacto positivo na satisfação no trabalho dos professores quando eles possuem um nível mais alto de comprometimento organizacional (CO), devido à moderação que esse fator exerce sobre o efeito do comprometimento organizacional (CO) dos professores na satisfação no trabalho. Assim, esta pesquisa aponta como o CO e a autoeficácia (AE) podem afetar a implementação da teoria da LD no ensino superior chinês, fornecendo novas evidências empíricas para essa abordagem.

Sheet Sheet4
A1: Continente | B1: Quantitade
A2: Ásia | B2: 43
A3: América Latina | B3: 18
A4: África | B4: 8
A5: Europa | B5: 4
